...F
======================================================================
FAIL: test_num_02 (unittest_test.TestNum.Test)
----------------------------------------------------------------------
Traceback (most recent call last):
  File "/Users/wuyanhong/PycharmProjects/App_Appium_Test/unittest_test/TestNum.py", line 22, in test_num_02
    self.assertNotIn("h", "hello") #失败
AssertionError: 'h' unexpectedly found in 'hello'

----------------------------------------------------------------------
Ran 4 tests in 0.001s

FAILED (failures=1)
test_add_01 (unittest_test.TestMath.Test) ... ok
test_add_02 (unittest_test.TestMath.Test) ... ok
test_num_01 (unittest_test.TestNum.Test) ... ok
test_num_02 (unittest_test.TestNum.Test) ... FAIL

======================================================================
FAIL: test_num_02 (unittest_test.TestNum.Test)
----------------------------------------------------------------------
Traceback (most recent call last):
  File "/Users/wuyanhong/PycharmProjects/App_Appium_Test/unittest_test/TestNum.py", line 22, in test_num_02
    self.assertNotIn("h", "hello") #失败
AssertionError: 'h' unexpectedly found in 'hello'

----------------------------------------------------------------------
Ran 4 tests in 0.002s

FAILED (failures=1)
